Workbook
Name cc: 三家公司!$J$11:$L$13
Name ccc: 四家公司!$L$14:$O$17
Name wpx: 四家公司!$L$36:$O$36
Name wpy: 四家公司!$L$43:$O$43
Name wx: 三家公司!$J$30:$L$30
Name wy: 三家公司!$J$36:$L$36

Sheet 三家公司
A1: 2308收盤價 | B1: 2881收盤價 | C1: 2603收盤價 | D1: R_2308 | E1: R_2881 | F1: R_2603 | I1: mu_2308 | J1: mu_2881 | K1: mu2603 | P1: alpha | Q1: 1-alpha | R1: Sigma(P) | S1: E(P) | T1: 變異係數的倒數=E(P)/Sigma(P) | U1: 變異係數=Sigma(P)/E(P) | X1: max= | Y1: =MAX(T:T) -> 2.1642385
A2: 310 | B2: 64.6 | C2: 151 | D2: =A3/A2-1 -> -0.017741935 | E2: =B3/B2-1 -> -0.013931889 | F2: =C3/C2-1 -> 0.026490066 | I2: =AVERAGE(D2:D242)*241 -> 0.38905536 | J2: =AVERAGE(E2:E242)*241 -> 0.36255254 | K2: =AVERAGE(F2:F242)*241 -> 0.48348282 | P2: -10 | Q2: =1-P2 -> 11 | R2: =SQRT(P2^2*$K$41+Q2^2*$K$42+2*P2*Q2*$K$43) -> 0.73910426 | S2: =P2*$K$39+Q2*$K$40 -> 0.58127802 | T2: =S2/R2 -> 0.78646282 | U2: =R2/S2 -> 1.2715159 | X2: min= | Y2: =MIN(U:U) -> 0.46205628
A3: 304.5 | B3: 63.7 | C3: 155 | D3: =A4/A3-1 -> -0.0016420361 | E3: =B4/B3-1 -> -0.0031397174 | F3: =C4/C3-1 -> 0.038709677 | I3: 變異數-共變異數矩陣 | P3: -9.99 | Q3: =1-P3 -> 10.99 | R3: =SQRT(P3^2*$K$41+Q3^2*$K$42+2*P3*Q3*$K$43) -> 0.7385052 | S3: =P3*$K$39+Q3*$K$40 -> 0.58111246 | T3: =S3/R3 -> 0.78687659 | U3: =R3/S3 -> 1.2708473 | W3: MVP | X3: =MIN(R2:R2002) -> 0.18127523
A4: 304 | B4: 63.5 | C4: 161 | D4: =A5/A4-1 -> 0.0016447368 | E4: =B5/B4-1 -> -0.0047244094 | F4: =C5/C4-1 -> 0.0093167702 | J4: R_2308 | K4: R_2881 | L4: R_2603 | P4: -9.98 | Q4: =1-P4 -> 10.98 | R4: =SQRT(P4^2*$K$41+Q4^2*$K$42+2*P4*Q4*$K$43) -> 0.73790618 | S4: =P4*$K$39+Q4*$K$40 -> 0.58094689 | T4: =S4/R4 -> 0.787291 | U4: =R4/S4 -> 1.2701784
A5: 304.5 | B5: 63.2 | C5: 162.5 | D5: =A6/A5-1 -> 0.0049261084 | E5: =B6/B5-1 -> 0.014240506 | F5: =C6/C5-1 -> -0.012307692 | I5: R_2308 | J5: =VARP(三家公司!$D$2:$D$242) -> 0.00050004609 | P5: -9.97 | Q5: =1-P5 -> 10.97 | R5: =SQRT(P5^2*$K$41+Q5^2*$K$42+2*P5*Q5*$K$43) -> 0.73730718 | S5: =P5*$K$39+Q5*$K$40 -> 0.58078133 | T5: =S5/R5 -> 0.78770606 | U5: =R5/S5 -> 1.2695091
A6: 306 | B6: 64.1 | C6: 160.5 | D6: =A7/A6-1 -> -0.034313725 | E6: =B7/B6-1 -> -0.0015600624 | F6: =C7/C6-1 -> -0.056074766 | I6: R_2881 | J6: 6.1367109e-06 | K6: =VARP(三家公司!$E$2:$E$242) -> 0.00022461854 | P6: -9.96 | Q6: =1-P6 -> 10.96 | R6: =SQRT(P6^2*$K$41+Q6^2*$K$42+2*P6*Q6*$K$43) -> 0.73670822 | S6: =P6*$K$39+Q6*$K$40 -> 0.58061577 | T6: =S6/R6 -> 0.78812175 | U6: =R6/S6 -> 1.2688395
A7: 295.5 | B7: 64 | C7: 151.5 | D7: =A8/A7-1 -> -0.015228426 | E7: =B8/B7-1 -> 0 | F7: =C8/C7-1 -> -0.02310231 | I7: R_2603 | J7: 3.0342e-06 | K7: 3.8099061e-05 | L7: =VARP(三家公司!$F$2:$F$242) -> 0.00069693907 | P7: -9.95 | Q7: =1-P7 -> 10.95 | R7: =SQRT(P7^2*$K$41+Q7^2*$K$42+2*P7*Q7*$K$43) -> 0.73610929 | S7: =P7*$K$39+Q7*$K$40 -> 0.58045021 | T7: =S7/R7 -> 0.78853809 | U7: =R7/S7 -> 1.2681696
A8: 291 | B8: 64 | C8: 148 | D8: =A9/A8-1 -> 0.0068728522 | E8: =B9/B8-1 -> -0.0015625 | F8: =C9/C8-1 -> 0.0067567568 | P8: -9.94 | Q8: =1-P8 -> 10.94 | R8: =SQRT(P8^2*$K$41+Q8^2*$K$42+2*P8*Q8*$K$43) -> 0.73551039 | S8: =P8*$K$39+Q8*$K$40 -> 0.58028465 | T8: =S8/R8 -> 0.78895507 | U8: =R8/S8 -> 1.2674993
A9: 293 | B9: 63.9 | C9: 149 | D9: =A10/A9-1 -> 0.0017064846 | E9: =B10/B9-1 -> 0.0031298905 | F9: =C10/C9-1 -> 0.05033557 | P9: -9.93 | Q9: =1-P9 -> 10.93 | R9: =SQRT(P9^2*$K$41+Q9^2*$K$42+2*P9*Q9*$K$43) -> 0.73491153 | S9: =P9*$K$39+Q9*$K$40 -> 0.58011909 | T9: =S9/R9 -> 0.78937269 | U9: =R9/S9 -> 1.2668287
A10: 293.5 | B10: 64.1 | C10: 156.5 | D10: =A11/A10-1 -> 0.0068143101 | E10: =B11/B10-1 -> 0 | F10: =C11/C10-1 -> 0.012779553 | I10: 年化 | J10: R_2308 | K10: R_2281 | L10: R_2603 | P10: -9.92 | Q10: =1-P10 -> 10.92 | R10: =SQRT(P10^2*$K$41+Q10^2*$K$42+2*P10*Q10*$K$43) -> 0.73431269 | S10: =P10*$K$39+Q10*$K$40 -> 0.57995353 | T10: =S10/R10 -> 0.78979097 | U10: =R10/S10 -> 1.2661578
A11: 295.5 | B11: 64.1 | C11: 158.5 | D11: =A12/A11-1 -> -0.020304569 | E11: =B12/B11-1 -> -0.014040562 | F11: =C12/C11-1 -> -0.031545741 | I11: R_2308 | J11: =J5*241 -> 0.12051111 | K11: 0.0014789473 | L11: 0.00073124219 | P11: -9.91 | Q11: =1-P11 -> 10.91 | R11: =SQRT(P11^2*$K$41+Q11^2*$K$42+2*P11*Q11*$K$43) -> 0.73371389 | S11: =P11*$K$39+Q11*$K$40 -> 0.57978797 | T11: =S11/R11 -> 0.79020989 | U11: =R11/S11 -> 1.2654866
A12: 289.5 | B12: 63.2 | C12: 153.5 | D12: =A13/A12-1 -> -0.034542314 | E12: =B13/B12-1 -> -0.014240506 | F12: =C13/C12-1 -> -0.006514658 | I12: R_2281 | J12: =J6*241 -> 0.0014789473 | K12: =K6*241 -> 0.054133069 | L12: 0.0091818738 | P12: -9.9 | Q12: =1-P12 -> 10.9 | R12: =SQRT(P12^2*$K$41+Q12^2*$K$42+2*P12*Q12*$K$43) -> 0.73311512 | S12: =P12*$K$39+Q12*$K$40 -> 0.57962241 | T12: =S12/R12 -> 0.79062946 | U12: =R12/S12 -> 1.264815
A13: 279.5 | B13: 62.3 | C13: 152.5 | D13: =A14/A13-1 -> -0.0089445438 | E13: =B14/B13-1 -> 0 | F13: =C14/C13-1 -> 0.036065574 | I13: R_2603 | J13: =J7*241 -> 0.00073124219 | K13: =K7*241 -> 0.0091818738 | L13: =L7*241 -> 0.16796231 | P13: -9.89 | Q13: =1-P13 -> 10.89 | R13: =SQRT(P13^2*$K$41+Q13^2*$K$42+2*P13*Q13*$K$43) -> 0.73251638 | S13: =P13*$K$39+Q13*$K$40 -> 0.57945685 | T13: =S13/R13 -> 0.79104969 | U13: =R13/S13 -> 1.2641431
A14: 277 | B14: 62.3 | C14: 158 | D14: =A15/A14-1 -> 0.028880866 | E14: =B15/B14-1 -> 0.011235955 | F14: =C15/C14-1 -> -0.018987342 | P14: -9.88 | Q14: =1-P14 -> 10.88 | R14: =SQRT(P14^2*$K$41+Q14^2*$K$42+2*P14*Q14*$K$43) -> 0.73191767 | S14: =P14*$K$39+Q14*$K$40 -> 0.57929129 | T14: =S14/R14 -> 0.79147056 | U14: =R14/S14 -> 1.2634709
A15: 285 | B15: 63 | C15: 155 | D15: =A16/A15-1 -> 0.021052632 | E15: =B16/B15-1 -> 0.0031746032 | F15: =C16/C15-1 -> -0.016129032 | P15: -9.87 | Q15: =1-P15 -> 10.87 | R15: =SQRT(P15^2*$K$41+Q15^2*$K$42+2*P15*Q15*$K$43) -> 0.73131899 | S15: =P15*$K$39+Q15*$K$40 -> 0.57912573 | T15: =S15/R15 -> 0.7918921 | U15: =R15/S15 -> 1.2627983
A16: 291 | B16: 63.2 | C16: 152.5 | D16: =A17/A16-1 -> 0.0085910653 | E16: =B17/B16-1 -> 0.011075949 | F16: =C17/C16-1 -> 0 | I16: 反矩陣 | J16: {=MINVERSE(J11:L13)} -> 8.300869 | K16: -0.22272003 | L16: -0.023963461 | P16: -9.86 | Q16: =1-P16 -> 10.86 | R16: =SQRT(P16^2*$K$41+Q16^2*$K$42+2*P16*Q16*$K$43) -> 0.73072035 | S16: =P16*$K$39+Q16*$K$40 -> 0.57896017 | T16: =S16/R16 -> 0.79231428 | U16: =R16/S16 -> 1.2621254
A17: 293.5 | B17: 63.9 | C17: 152.5 | D17: =A18/A17-1 -> -0.015332198 | E17: =B18/B17-1 -> 0.0078247261 | F17: =C18/C17-1 -> 0.006557377 | J17: -0.22272003 | K17: 18.651863 | L17: -1.0186582 | P17: -9.85 | Q17: =1-P17 -> 10.85 | R17: =SQRT(P17^2*$K$41+Q17^2*$K$42+2*P17*Q17*$K$43) -> 0.73012174 | S17: =P17*$K$39+Q17*$K$40 -> 0.57879461 | T17: =S17/R17 -> 0.79273713 | U17: =R17/S17 -> 1.2614522
A18: 289 | B18: 64.4 | C18: 153.5 | D18: =A19/A18-1 -> -0.017301038 | E18: =B19/B18-1 -> 0.0031055901 | F18: =C19/C18-1 -> -0.013029316 | J18: -0.023963461 | K18: -1.0186582 | L18: 6.009507 | P18: -9.84 | Q18: =1-P18 -> 10.84 | R18: =SQRT(P18^2*$K$41+Q18^2*$K$42+2*P18*Q18*$K$43) -> 0.72952316 | S18: =P18*$K$39+Q18*$K$40 -> 0.57862905 | T18: =S18/R18 -> 0.79316063 | U18: =R18/S18 -> 1.2607787
A19: 284 | B19: 64.6 | C19: 151.5 | D19: =A20/A19-1 -> 0.012323944 | E19: =B20/B19-1 -> 0.0030959752 | F19: =C20/C19-1 -> -0.00330033 | P19: -9.83 | Q19: =1-P19 -> 10.83 | R19: =SQRT(P19^2*$K$41+Q19^2*$K$42+2*P19*Q19*$K$43) -> 0.72892461 | S19: =P19*$K$39+Q19*$K$40 -> 0.57846349 | T19: =S19/R19 -> 0.7935848 | U19: =R19/S19 -> 1.2601048
A20: 287.5 | B20: 64.8 | C20: 151 | D20: =A21/A20-1 -> 0.019130435 | E20: =B21/B20-1 -> 0 | F20: =C21/C20-1 -> 0.0033112583 | P20: -9.82 | Q20: =1-P20 -> 10.82 | R20: =SQRT(P20^2*$K$41+Q20^2*$K$42+2*P20*Q20*$K$43) -> 0.72832609 | S20: =P20*$K$39+Q20*$K$40 -> 0.57829793 | T20: =S20/R20 -> 0.79400962 | U20: =R20/S20 -> 1.2594306
A21: 293 | B21: 64.8 | C21: 151.5 | D21: =A22/A21-1 -> -0.023890785 | E21: =B22/B21-1 -> -0.0077160494 | F21: =C22/C21-1 -> 0 | I21: 測試 | J21: {=MMULT(J11:L13,_xlfn.ANCHORARRAY(J16))} -> 1 | K21: -1.6263033e-18 | L21: 0 | P21: -9.81 | Q21: =1-P21 -> 10.81 | R21: =SQRT(P21^2*$K$41+Q21^2*$K$42+2*P21*Q21*$K$43) -> 0.72772761 | S21: =P21*$K$39+Q21*$K$40 -> 0.57813237 | T21: =S21/R21 -> 0.79443511 | U21: =R21/S21 -> 1.258756
A22: 286 | B22: 64.3 | C22: 151.5 | D22: =A23/A22-1 -> -0.020979021 | E22: =B23/B22-1 -> 0.0031104199 | F22: =C23/C22-1 -> -0.0066006601 | J22: 2.8189256e-18 | K22: 1 | L22: 0 | P22: -9.8 | Q22: =1-P22 -> 10.8 | R22: =SQRT(P22^2*$K$41+Q22^2*$K$42+2*P22*Q22*$K$43) -> 0.72712916 | S22: =P22*$K$39+Q22*$K$40 -> 0.57796681 | T22: =S22/R22 -> 0.79486127 | U22: =R22/S22 -> 1.2580812
A23: 280 | B23: 64.5 | C23: 150.5 | D23: =A24/A23-1 -> 0.017857143 | E23: =B24/B23-1 -> 0.0046511628 | F23: =C24/C23-1 -> 0.043189369 | J23: 1.7347235e-18 | K23: 0 | L23: 1 | P23: -9.79 | Q23: =1-P23 -> 10.79 | R23: =SQRT(P23^2*$K$41+Q23^2*$K$42+2*P23*Q23*$K$43) -> 0.72653074 | S23: =P23*$K$39+Q23*$K$40 -> 0.57780124 | T23: =S23/R23 -> 0.79528809 | U23: =R23/S23 -> 1.257406
A24: 285 | B24: 64.8 | C24: 157 | D24: =A25/A24-1 -> 0.0035087719 | E24: =B25/B24-1 -> 0.0015432099 | F24: =C25/C24-1 -> -0.044585987 | P24: -9.78 | Q24: =1-P24 -> 10.78 | R24: =SQRT(P24^2*$K$41+Q24^2*$K$42+2*P24*Q24*$K$43) -> 0.72593236 | S24: =P24*$K$39+Q24*$K$40 -> 0.57763568 | T24: =S24/R24 -> 0.79571557 | U24: =R24/S24 -> 1.2567305
A25: 286 | B25: 64.9 | C25: 150 | D25: =A26/A25-1 -> 0.0052447552 | E25: =B26/B25-1 -> -0.0030816641 | F25: =C26/C25-1 -> 0.013333333 | P25: -9.77 | Q25: =1-P25 -> 10.77 | R25: =SQRT(P25^2*$K$41+Q25^2*$K$42+2*P25*Q25*$K$43) -> 0.72533401 | S25: =P25*$K$39+Q25*$K$40 -> 0.57747012 | T25: =S25/R25 -> 0.79614373 | U25: =R25/S25 -> 1.2560546
A26: 287.5 | B26: 64.7 | C26: 152 | D26: =A27/A26-1 -> -0.010434783 | E26: =B27/B26-1 -> 0.0092735703 | F26: =C27/C26-1 -> -0.019736842 | I26: Rx | J26: dx | K26: 0.15 | P26: -9.76 | Q26: =1-P26 -> 10.76 | R26: =SQRT(P26^2*$K$41+Q26^2*$K$42+2*P26*Q26*$K$43) -> 0.72473569 | S26: =P26*$K$39+Q26*$K$40 -> 0.57730456 | T26: =S26/R26 -> 0.79657256 | U26: =R26/S26 -> 1.2553784
A27: 284.5 | B27: 65.3 | C27: 149 | D27: =A28/A27-1 -> 0.024604569 | E27: =B28/B27-1 -> 0.0091883614 | F27: =C28/C27-1 -> -0.0067114094 | I27: Zx | J27: 2308 | K27: 2881 | L27: 2603 | P27: -9.75 | Q27: =1-P27 -> 10.75 | R27: =SQRT(P27^2*$K$41+Q27^2*$K$42+2*P27*Q27*$K$43) -> 0.7241374 | S27: =P27*$K$39+Q27*$K$40 -> 0.577139 | T27: =S27/R27 -> 0.79700206 | U27: =R27/S27 -> 1.2547019
A28: 291.5 | B28: 65.9 | C28: 148 | D28: =A29/A28-1 -> 0.0017152659 | E28: =B29/B28-1 -> 0.0030349014 | F28: =C29/C28-1 -> 0.0067567568 | J28: {=MMULT(I2:K2-$K$26,J16:L18)} -> 1.9290361 | K28: 3.5715534 | L28: 1.7818204 | M28: =SUM(_xlfn.ANCHORARRAY(J28)) -> 7.2824099 | P28: -9.74 | Q28: =1-P28 -> 10.74 | R28: =SQRT(P28^2*$K$41+Q28^2*$K$42+2*P28*Q28*$K$43) -> 0.72353915 | S28: =P28*$K$39+Q28*$K$40 -> 0.57697344 | T28: =S28/R28 -> 0.79743224 | U28: =R28/S28 -> 1.2540251
A29: 292 | B29: 66.1 | C29: 149 | D29: =A30/A29-1 -> 0.0017123288 | E29: =B30/B29-1 -> 0.0060514372 | F29: =C30/C29-1 -> 0.030201342 | I29: wx | J29: 2308 | K29: 2881 | L29: 2603 | P29: -9.73 | Q29: =1-P29 -> 10.73 | R29: =SQRT(P29^2*$K$41+Q29^2*$K$42+2*P29*Q29*$K$43) -> 0.72294093 | S29: =P29*$K$39+Q29*$K$40 -> 0.57680788 | T29: =S29/R29 -> 0.79786309 | U29: =R29/S29 -> 1.2533479
A30: 292.5 | B30: 66.5 | C30: 153.5 | D30: =A31/A30-1 -> -0.0051282051 | E30: =B31/B30-1 -> -0.0030075188 | F30: =C31/C30-1 -> 0.009771987 | J30: =J28/M28 -> 0.2648898 | K30: =K28/M28 -> 0.49043565 | L30: =L28/M28 -> 0.24467455 | M30: =SUM(J30:L30) -> 1 | P30: -9.72 | Q30: =1-P30 -> 10.72 | R30: =SQRT(P30^2*$K$41+Q30^2*$K$42+2*P30*Q30*$K$43) -> 0.72234274 | S30: =P30*$K$39+Q30*$K$40 -> 0.57664232 | T30: =S30/R30 -> 0.79829461 | U30: =R30/S30 -> 1.2526704
A31: 291 | B31: 66.3 | C31: 155 | D31: =A32/A31-1 -> 0.0085910653 | E31: =B32/B31-1 -> 0.0030165913 | F31: =C32/C31-1 -> 0.048387097 | P31: -9.71 | Q31: =1-P31 -> 10.71 | R31: =SQRT(P31^2*$K$41+Q31^2*$K$42+2*P31*Q31*$K$43) -> 0.72174459 | S31: =P31*$K$39+Q31*$K$40 -> 0.57647676 | T31: =S31/R31 -> 0.79872682 | U31: =R31/S31 -> 1.2519925
A32: 293.5 | B32: 66.5 | C32: 162.5 | D32: =A33/A32-1 -> -0.003407155 | E32: =B33/B32-1 -> 0.0015037594 | F32: =C33/C32-1 -> -0.018461538 | I32: Ry | J32: dy | K32: 0.3 | P32: -9.7 | Q32: =1-P32 -> 10.7 | R32: =SQRT(P32^2*$K$41+Q32^2*$K$42+2*P32*Q32*$K$43) -> 0.72114647 | S32: =P32*$K$39+Q32*$K$40 -> 0.5763112 | T32: =S32/R32 -> 0.7991597 | U32: =R32/S32 -> 1.2513143
A33: 292.5 | B33: 66.6 | C33: 159.5 | D33: =A34/A33-1 -> 0.0085470085 | E33: =B34/B33-1 -> 0.0045045045 | F33: =C34/C33-1 -> 0.0031347962 | I33: zy | J33: 2308 | K33: 2881 | L33: 2603 | P33: -9.69 | Q33: =1-P33 -> 10.69 | R33: =SQRT(P33^2*$K$41+Q33^2*$K$42+2*P33*Q33*$K$43) -> 0.72054838 | S33: =P33*$K$39+Q33*$K$40 -> 0.57614564 | T33: =S33/R33 -> 0.79959327 | U33: =R33/S33 -> 1.2506358
A34: 295 | B34: 66.9 | C34: 160 | D34: =A35/A34-1 -> -0.020338983 | E34: =B35/B34-1 -> 0 | F34: =C35/C34-1 -> -0.003125 | J34: {=MMULT(I2:K2-$K$32,J16:L18)} -> 0.72090826 | K34: 0.95998067 | L34: 1.0367876 | M34: =SUM(_xlfn.ANCHORARRAY(J34)) -> 2.7176765 | P34: -9.68 | Q34: =1-P34 -> 10.68 | R34: =SQRT(P34^2*$K$41+Q34^2*$K$42+2*P34*Q34*$K$43) -> 0.71995033 | S34: =P34*$K$39+Q34*$K$40 -> 0.57598008 | T34: =S34/R34 -> 0.80002752 | U34: =R34/S34 -> 1.249957
A35: 289 | B35: 66.9 | C35: 159.5 | D35: =A36/A35-1 -> 0.019031142 | E35: =B36/B35-1 -> 0.016442451 | F35: =C36/C35-1 -> 0.037617555 | I35: wy | J35: 2308 | K35: 2881 | L35: 2603 | P35: -9.67 | Q35: =1-P35 -> 10.67 | R35: =SQRT(P35^2*$K$41+Q35^2*$K$42+2*P35*Q35*$K$43) -> 0.71935231 | S35: =P35*$K$39+Q35*$K$40 -> 0.57581452 | T35: =S35/R35 -> 0.80046246 | U35: =R35/S35 -> 1.2492778
A36: 294.5 | B36: 68 | C36: 165.5 | D36: =A37/A36-1 -> -0.0033955857 | E36: =B37/B36-1 -> -0.0088235294 | F36: =C37/C36-1 -> -0.003021148 | J36: =J34/M34 -> 0.2652664 | K36: =K34/M34 -> 0.35323581 | L36: =L34/M34 -> 0.38149779 | M36: =SUM(J36:L36) -> 1 | P36: -9.66 | Q36: =1-P36 -> 10.66 | R36: =SQRT(P36^2*$K$41+Q36^2*$K$42+2*P36*Q36*$K$43) -> 0.71875433 | S36: =P36*$K$39+Q36*$K$40 -> 0.57564896 | T36: =S36/R36 -> 0.80089808 | U36: =R36/S36 -> 1.2485983
A37: 293.5 | B37: 67.4 | C37: 165 | D37: =A38/A37-1 -> 0 | E37: =B38/B37-1 -> 0 | F37: =C38/C37-1 -> 0.042424242 | P37: -9.65 | Q37: =1-P37 -> 10.65 | R37: =SQRT(P37^2*$K$41+Q37^2*$K$42+2*P37*Q37*$K$43) -> 0.71815637 | S37: =P37*$K$39+Q37*$K$40 -> 0.5754834 | T37: =S37/R37 -> 0.80133439 | U37: =R37/S37 -> 1.2479185
A38: 293.5 | B38: 67.4 | C38: 172 | D38: =A39/A38-1 -> -0.010221465 | E38: =B39/B38-1 -> -0.0014836795 | F38: =C39/C38-1 -> 0.0087209302 | P38: -9.64 | Q38: =1-P38 -> 10.64 | R38: =SQRT(P38^2*$K$41+Q38^2*$K$42+2*P38*Q38*$K$43) -> 0.71755846 | S38: =P38*$K$39+Q38*$K$40 -> 0.57531784 | T38: =S38/R38 -> 0.80177138 | U38: =R38/S38 -> 1.2472383
A39: 290.5 | B39: 67.3 | C39: 173.5 | D39: =A40/A39-1 -> 0.015490534 | E39: =B40/B39-1 -> 0 | F39: =C40/C39-1 -> -0.011527378 | J39: E(Rx) | K39: {=MMULT(I2:K2,TRANSPOSE(wx))} -> 0.39916143 | P39: -9.63 | Q39: =1-P39 -> 10.63 | R39: =SQRT(P39^2*$K$41+Q39^2*$K$42+2*P39*Q39*$K$43) -> 0.71696057 | S39: =P39*$K$39+Q39*$K$40 -> 0.57515228 | T39: =S39/R39 -> 0.80220907 | U39: =R39/S39 -> 1.2465578
A40: 295 | B40: 67.3 | C40: 171.5 | D40: =A41/A40-1 -> 0.006779661 | E40: =B41/B40-1 -> 0.011887073 | F40: =C41/C40-1 -> 0.034985423 | J40: E(Ry) | K40: {=MMULT(I2:K2,TRANSPOSE(wy))} -> 0.41571748 | P40: -9.62 | Q40: =1-P40 -> 10.62 | R40: =SQRT(P40^2*$K$41+Q40^2*$K$42+2*P40*Q40*$K$43) -> 0.71636272 | S40: =P40*$K$39+Q40*$K$40 -> 0.57498672 | T40: =S40/R40 -> 0.80264745 | U40: =R40/S40 -> 1.245877
...

Sheet 四家公司
A1: 2308收盤價 | B1: 2881收盤價 | C1: 2603收盤價 | D1: 4904收盤價 | F1: R_2308 | G1: R_2881 | H1: R_2603 | I1: R_4904 | K1: mu_2308 | L1: mu_2881 | M1: mu_2603 | N1: mu_4904 | R1: alpha | S1: 1-alpha | T1: Sigma(P) | U1: E(P) | V1: 變異係數的倒數=E(P)/Sigma(P) | W1: 變異係數=Sigma(P)/E(P) | Z1: max= | AA1: =MAX(V:V) -> 2.2300679
A2: 310 | B2: 64.6 | C2: 151 | D2: 79.9 | F2: =A3/A2-1 -> -0.017741935 | G2: =B3/B2-1 -> -0.013931889 | H2: =C3/C2-1 -> 0.026490066 | I2: =D3/D2-1 -> -0.0062578223 | K2: =AVERAGE(F2:F242)*241 -> 0.38905536 | L2: =AVERAGE(G2:G242)*241 -> 0.36255254 | M2: =AVERAGE(H2:H242)*241 -> 0.48348282 | N2: =AVERAGE(I2:I242)*241 -> 0.13014439 | R2: -10 | S2: =1-R2 -> 11 | T2: =SQRT(R2^2*$L$48+S2^2*$L$49+2*R2*S2*$L$50) -> 0.4524153 | U2: =R2*$L$46+S2*$L$47 -> 0.72403614 | V2: =U2/T2 -> 1.6003794 | W2: =T2/U2 -> 0.62485182 | Z2: min= | AA2: =MIN(W2:W2002) -> 0.44841683
A3: 304.5 | B3: 63.7 | C3: 155 | D3: 79.4 | F3: =A4/A3-1 -> -0.0016420361 | G3: =B4/B3-1 -> -0.0031397174 | H3: =C4/C3-1 -> 0.038709677 | I3: =D4/D3-1 -> 0 | R3: -9.99 | S3: =1-R3 -> 10.99 | T3: =SQRT(R3^2*$L$48+S3^2*$L$49+2*R3*S3*$L$50) -> 0.45211918 | U3: =R3*$L$46+S3*$L$47 -> 0.7237063 | V3: =U3/T3 -> 1.6006981 | W3: =T3/U3 -> 0.62472743
A4: 304 | B4: 63.5 | C4: 161 | D4: 79.4 | F4: =A5/A4-1 -> 0.0016447368 | G4: =B5/B4-1 -> -0.0047244094 | H4: =C5/C4-1 -> 0.0093167702 | I4: =D5/D4-1 -> -0.0037783375 | R4: -9.98 | S4: =1-R4 -> 10.98 | T4: =SQRT(R4^2*$L$48+S4^2*$L$49+2*R4*S4*$L$50) -> 0.45182308 | U4: =R4*$L$46+S4*$L$47 -> 0.72337647 | V4: =U4/T4 -> 1.6010171 | W4: =T4/U4 -> 0.62460295
A5: 304.5 | B5: 63.2 | C5: 162.5 | D5: 79.1 | F5: =A6/A5-1 -> 0.0049261084 | G5: =B6/B5-1 -> 0.014240506 | H5: =C6/C5-1 -> -0.012307692 | I5: =D6/D5-1 -> 0.007585335 | K5: 變異數-共變異數矩陣 | R5: -9.97 | S5: =1-R5 -> 10.97 | T5: =SQRT(R5^2*$L$48+S5^2*$L$49+2*R5*S5*$L$50) -> 0.451527 | U5: =R5*$L$46+S5*$L$47 -> 0.72304663 | V5: =U5/T5 -> 1.6013364 | W5: =T5/U5 -> 0.62447839 | Y5: MVP | Z5: =MIN(T2:T2002) -> 0.13525525
A6: 306 | B6: 64.1 | C6: 160.5 | D6: 79.7 | F6: =A7/A6-1 -> -0.034313725 | G6: =B7/B6-1 -> -0.0015600624 | H6: =C7/C6-1 -> -0.056074766 | I6: =D7/D6-1 -> 0.0037641154 | L6: R_2308 | M6: R_2881 | N6: R_2603 | O6: R_4904 | R6: -9.96 | S6: =1-R6 -> 10.96 | T6: =SQRT(R6^2*$L$48+S6^2*$L$49+2*R6*S6*$L$50) -> 0.45123093 | U6: =R6*$L$46+S6*$L$47 -> 0.7227168 | V6: =U6/T6 -> 1.6016561 | W6: =T6/U6 -> 0.62435374
A7: 295.5 | B7: 64 | C7: 151.5 | D7: 80 | F7: =A8/A7-1 -> -0.015228426 | G7: =B8/B7-1 -> 0 | H7: =C8/C7-1 -> -0.02310231 | I7: =D8/D7-1 -> 0.00125 | K7: R_2308 | L7: =VARP(四家公司!$F$2:$F$242) -> 0.00050004609 | R7: -9.95 | S7: =1-R7 -> 10.95 | T7: =SQRT(R7^2*$L$48+S7^2*$L$49+2*R7*S7*$L$50) -> 0.45093489 | U7: =R7*$L$46+S7*$L$47 -> 0.72238696 | V7: =U7/T7 -> 1.6019762 | W7: =T7/U7 -> 0.624229
A8: 291 | B8: 64 | C8: 148 | D8: 80.1 | F8: =A9/A8-1 -> 0.0068728522 | G8: =B9/B8-1 -> -0.0015625 | H8: =C9/C8-1 -> 0.0067567568 | I8: =D9/D8-1 -> 0.014981273 | K8: R_2881 | L8: 6.1367109e-06 | M8: =VARP(四家公司!$G$2:$G$242) -> 0.00022461854 | R8: -9.94 | S8: =1-R8 -> 10.94 | T8: =SQRT(R8^2*$L$48+S8^2*$L$49+2*R8*S8*$L$50) -> 0.45063886 | U8: =R8*$L$46+S8*$L$47 -> 0.72205712 | V8: =U8/T8 -> 1.6022966 | W8: =T8/U8 -> 0.62410417
A9: 293 | B9: 63.9 | C9: 149 | D9: 81.3 | F9: =A10/A9-1 -> 0.0017064846 | G9: =B10/B9-1 -> 0.0031298905 | H9: =C10/C9-1 -> 0.05033557 | I9: =D10/D9-1 -> -0.0012300123 | K9: R_2603 | L9: 3.0342e-06 | M9: 3.8099061e-05 | N9: =VARP(四家公司!$H$2:$H$242) -> 0.00069693907 | R9: -9.93 | S9: =1-R9 -> 10.93 | T9: =SQRT(R9^2*$L$48+S9^2*$L$49+2*R9*S9*$L$50) -> 0.45034286 | U9: =R9*$L$46+S9*$L$47 -> 0.72172729 | V9: =U9/T9 -> 1.6026174 | W9: =T9/U9 -> 0.62397926
A10: 293.5 | B10: 64.1 | C10: 156.5 | D10: 81.2 | F10: =A11/A10-1 -> 0.0068143101 | G10: =B11/B10-1 -> 0 | H10: =C11/C10-1 -> 0.012779553 | I10: =D11/D10-1 -> 0 | K10: R_4904 | L10: 3.2480531e-06 | M10: 1.5940068e-05 | N10: 5.5856501e-06 | O10: =VARP(四家公司!$I$2:$I$242) -> 0.00014613682 | R10: -9.92 | S10: =1-R10 -> 10.92 | T10: =SQRT(R10^2*$L$48+S10^2*$L$49+2*R10*S10*$L$50) -> 0.45004687 | U10: =R10*$L$46+S10*$L$47 -> 0.72139745 | V10: =U10/T10 -> 1.6029385 | W10: =T10/U10 -> 0.62385426
A11: 295.5 | B11: 64.1 | C11: 158.5 | D11: 81.2 | F11: =A12/A11-1 -> -0.020304569 | G11: =B12/B11-1 -> -0.014040562 | H11: =C12/C11-1 -> -0.031545741 | I11: =D12/D11-1 -> -0.018472906 | R11: -9.91 | S11: =1-R11 -> 10.91 | T11: =SQRT(R11^2*$L$48+S11^2*$L$49+2*R11*S11*$L$50) -> 0.44975091 | U11: =R11*$L$46+S11*$L$47 -> 0.72106762 | V11: =U11/T11 -> 1.60326 | W11: =T11/U11 -> 0.62372917
A12: 289.5 | B12: 63.2 | C12: 153.5 | D12: 79.7 | F12: =A13/A12-1 -> -0.034542314 | G12: =B13/B12-1 -> -0.014240506 | H12: =C13/C12-1 -> -0.006514658 | I12: =D13/D12-1 -> -0.008782936 | K12: 年化 | R12: -9.9 | S12: =1-R12 -> 10.9 | T12: =SQRT(R12^2*$L$48+S12^2*$L$49+2*R12*S12*$L$50) -> 0.44945496 | U12: =R12*$L$46+S12*$L$47 -> 0.72073778 | V12: =U12/T12 -> 1.6035818 | W12: =T12/U12 -> 0.62360399
A13: 279.5 | B13: 62.3 | C13: 152.5 | D13: 79 | F13: =A14/A13-1 -> -0.0089445438 | G13: =B14/B13-1 -> 0 | H13: =C14/C13-1 -> 0.036065574 | I13: =D14/D13-1 -> 0.0063291139 | L13: R_2308 | M13: R_2881 | N13: R_2603 | O13: R_4904 | R13: -9.89 | S13: =1-R13 -> 10.89 | T13: =SQRT(R13^2*$L$48+S13^2*$L$49+2*R13*S13*$L$50) -> 0.44915903 | U13: =R13*$L$46+S13*$L$47 -> 0.72040795 | V13: =U13/T13 -> 1.603904 | W13: =T13/U13 -> 0.62347873
A14: 277 | B14: 62.3 | C14: 158 | D14: 79.5 | F14: =A15/A14-1 -> 0.028880866 | G14: =B15/B14-1 -> 0.011235955 | H14: =C15/C14-1 -> -0.018987342 | I14: =D15/D14-1 -> 0.0012578616 | K14: R_2308 | L14: =L7*241 -> 0.12051111 | M14: 0.0014789473 | N14: 0.00073124219 | O14: 0.0007827808 | R14: -9.88 | S14: =1-R14 -> 10.88 | T14: =SQRT(R14^2*$L$48+S14^2*$L$49+2*R14*S14*$L$50) -> 0.44886312 | U14: =R14*$L$46+S14*$L$47 -> 0.72007811 | V14: =U14/T14 -> 1.6042265 | W14: =T14/U14 -> 0.62335338
A15: 285 | B15: 63 | C15: 155 | D15: 79.6 | F15: =A16/A15-1 -> 0.021052632 | G15: =B16/B15-1 -> 0.0031746032 | H15: =C16/C15-1 -> -0.016129032 | I15: =D16/D15-1 -> -0.0025125628 | K15: R_2881 | L15: =L8*241 -> 0.0014789473 | M15: =M8*241 -> 0.054133069 | N15: 0.0091818738 | O15: 0.0038415565 | R15: -9.87 | S15: =1-R15 -> 10.87 | T15: =SQRT(R15^2*$L$48+S15^2*$L$49+2*R15*S15*$L$50) -> 0.44856723 | U15: =R15*$L$46+S15*$L$47 -> 0.71974827 | V15: =U15/T15 -> 1.6045494 | W15: =T15/U15 -> 0.62322794
A16: 291 | B16: 63.2 | C16: 152.5 | D16: 79.4 | F16: =A17/A16-1 -> 0.0085910653 | G16: =B17/B16-1 -> 0.011075949 | H16: =C17/C16-1 -> 0 | I16: =D17/D16-1 -> 0 | K16: R_2603 | L16: =L9*241 -> 0.00073124219 | M16: =M9*241 -> 0.0091818738 | N16: =N9*241 -> 0.16796231 | O16: 0.0013461417 | R16: -9.86 | S16: =1-R16 -> 10.86 | T16: =SQRT(R16^2*$L$48+S16^2*$L$49+2*R16*S16*$L$50) -> 0.44827136 | U16: =R16*$L$46+S16*$L$47 -> 0.71941844 | V16: =U16/T16 -> 1.6048726 | W16: =T16/U16 -> 0.62310241
A17: 293.5 | B17: 63.9 | C17: 152.5 | D17: 79.4 | F17: =A18/A17-1 -> -0.015332198 | G17: =B18/B17-1 -> 0.0078247261 | H17: =C18/C17-1 -> 0.006557377 | I17: =D18/D17-1 -> -0.0012594458 | K17: R_4904 | L17: =L10*241 -> 0.0007827808 | M17: =M10*241 -> 0.0038415565 | N17: =N10*241 -> 0.0013461417 | O17: =O10*241 -> 0.035218974 | R17: -9.85 | S17: =1-R17 -> 10.85 | T17: =SQRT(R17^2*$L$48+S17^2*$L$49+2*R17*S17*$L$50) -> 0.44797551 | U17: =R17*$L$46+S17*$L$47 -> 0.7190886 | V17: =U17/T17 -> 1.6051962 | W17: =T17/U17 -> 0.62297679
A18: 289 | B18: 64.4 | C18: 153.5 | D18: 79.3 | F18: =A19/A18-1 -> -0.017301038 | G18: =B19/B18-1 -> 0.0031055901 | H18: =C19/C18-1 -> -0.013029316 | I18: =D19/D18-1 -> 0.0050441362 | R18: -9.84 | S18: =1-R18 -> 10.84 | T18: =SQRT(R18^2*$L$48+S18^2*$L$49+2*R18*S18*$L$50) -> 0.44767968 | U18: =R18*$L$46+S18*$L$47 -> 0.71875877 | V18: =U18/T18 -> 1.6055202 | W18: =T18/U18 -> 0.62285109
A19: 284 | B19: 64.6 | C19: 151.5 | D19: 79.7 | F19: =A20/A19-1 -> 0.012323944 | G19: =B20/B19-1 -> 0.0030959752 | H19: =C20/C19-1 -> -0.00330033 | I19: =D20/D19-1 -> 0.0012547051 | R19: -9.83 | S19: =1-R19 -> 10.83 | T19: =SQRT(R19^2*$L$48+S19^2*$L$49+2*R19*S19*$L$50) -> 0.44738387 | U19: =R19*$L$46+S19*$L$47 -> 0.71842893 | V19: =U19/T19 -> 1.6058445 | W19: =T19/U19 -> 0.6227253
A20: 287.5 | B20: 64.8 | C20: 151 | D20: 79.8 | F20: =A21/A20-1 -> 0.019130435 | G20: =B21/B20-1 -> 0 | H20: =C21/C20-1 -> 0.0033112583 | I20: =D21/D20-1 -> -0.0025062657 | K20: 反矩陣 | L20: {=MINVERSE(L14:O17)} -> 8.3017697 | M20: -0.21146372 | N20: -0.023295908 | O20: -0.16055995 | R20: -9.82 | S20: =1-R20 -> 10.82 | T20: =SQRT(R20^2*$L$48+S20^2*$L$49+2*R20*S20*$L$50) -> 0.44708808 | U20: =R20*$L$46+S20*$L$47 -> 0.7180991 | V20: =U20/T20 -> 1.6061692 | W20: =T20/U20 -> 0.62259942
A21: 293 | B21: 64.8 | C21: 151.5 | D21: 79.6 | F21: =A22/A21-1 -> -0.023890785 | G21: =B22/B21-1 -> -0.0077160494 | H21: =C22/C21-1 -> 0 | I21: =D22/D21-1 -> 0.006281407 | L21: -0.21146372 | M21: 18.792532 | N21: -1.0103158 | O21: -2.0065041 | R21: -9.81 | S21: =1-R21 -> 10.81 | T21: =SQRT(R21^2*$L$48+S21^2*$L$49+2*R21*S21*$L$50) -> 0.44679231 | U21: =R21*$L$46+S21*$L$47 -> 0.71776926 | V21: =U21/T21 -> 1.6064942 | W21: =T21/U21 -> 0.62247345
A22: 286 | B22: 64.3 | C22: 151.5 | D22: 80.1 | F22: =A23/A22-1 -> -0.020979021 | G22: =B23/B22-1 -> 0.0031104199 | H22: =C23/C22-1 -> -0.0066006601 | I22: =D23/D22-1 -> 0.0049937578 | L22: -0.023295908 | M22: -1.0103158 | N22: 6.0100018 | O22: -0.11899532 | R22: -9.8 | S22: =1-R22 -> 10.8 | T22: =SQRT(R22^2*$L$48+S22^2*$L$49+2*R22*S22*$L$50) -> 0.44649656 | U22: =R22*$L$46+S22*$L$47 -> 0.71743943 | V22: =U22/T22 -> 1.6068196 | W22: =T22/U22 -> 0.62234739
A23: 280 | B23: 64.5 | C23: 150.5 | D23: 80.5 | F23: =A24/A23-1 -> 0.017857143 | G23: =B24/B23-1 -> 0.0046511628 | H23: =C24/C23-1 -> 0.043189369 | I23: =D24/D23-1 -> -0.001242236 | L23: -0.16055995 | M23: -2.0065041 | N23: -0.11899532 | O23: 28.620765 | R23: -9.79 | S23: =1-R23 -> 10.79 | T23: =SQRT(R23^2*$L$48+S23^2*$L$49+2*R23*S23*$L$50) -> 0.44620082 | U23: =R23*$L$46+S23*$L$47 -> 0.71710959 | V23: =U23/T23 -> 1.6071454 | W23: =T23/U23 -> 0.62222125
A24: 285 | B24: 64.8 | C24: 157 | D24: 80.4 | F24: =A25/A24-1 -> 0.0035087719 | G24: =B25/B24-1 -> 0.0015432099 | H24: =C25/C24-1 -> -0.044585987 | I24: =D25/D24-1 -> -0.0074626866 | R24: -9.78 | S24: =1-R24 -> 10.78 | T24: =SQRT(R24^2*$L$48+S24^2*$L$49+2*R24*S24*$L$50) -> 0.44590511 | U24: =R24*$L$46+S24*$L$47 -> 0.71677975 | V24: =U24/T24 -> 1.6074715 | W24: =T24/U24 -> 0.62209501
A25: 286 | B25: 64.9 | C25: 150 | D25: 79.8 | F25: =A26/A25-1 -> 0.0052447552 | G25: =B26/B25-1 -> -0.0030816641 | H25: =C26/C25-1 -> 0.013333333 | I25: =D26/D25-1 -> -0.0050125313 | R25: -9.77 | S25: =1-R25 -> 10.77 | T25: =SQRT(R25^2*$L$48+S25^2*$L$49+2*R25*S25*$L$50) -> 0.44560942 | U25: =R25*$L$46+S25*$L$47 -> 0.71644992 | V25: =U25/T25 -> 1.607798 | W25: =T25/U25 -> 0.62196869
A26: 287.5 | B26: 64.7 | C26: 152 | D26: 79.4 | F26: =A27/A26-1 -> -0.010434783 | G26: =B27/B26-1 -> 0.0092735703 | H26: =C27/C26-1 -> -0.019736842 | I26: =D27/D26-1 -> 0.0088161209 | K26: 測試 | L26: {=MMULT(L14:O17,_xlfn.ANCHORARRAY(L20))} -> 1 | M26: 1.7347235e-18 | N26: 8.1315163e-20 | O26: 0 | R26: -9.76 | S26: =1-R26 -> 10.76 | T26: =SQRT(R26^2*$L$48+S26^2*$L$49+2*R26*S26*$L$50) -> 0.44531375 | U26: =R26*$L$46+S26*$L$47 -> 0.71612008 | V26: =U26/T26 -> 1.6081248 | W26: =T26/U26 -> 0.62184228
A27: 284.5 | B27: 65.3 | C27: 149 | D27: 80.1 | F27: =A28/A27-1 -> 0.024604569 | G27: =B28/B27-1 -> 0.0091883614 | H27: =C28/C27-1 -> -0.0067114094 | I27: =D28/D27-1 -> -0.0062421973 | L27: -5.4210109e-19 | M27: 1 | N27: -2.1684043e-19 | O27: 0 | R27: -9.75 | S27: =1-R27 -> 10.75 | T27: =SQRT(R27^2*$L$48+S27^2*$L$49+2*R27*S27*$L$50) -> 0.44501809 | U27: =R27*$L$46+S27*$L$47 -> 0.71579025 | V27: =U27/T27 -> 1.608452 | W27: =T27/U27 -> 0.62171578
A28: 291.5 | B28: 65.9 | C28: 148 | D28: 79.6 | F28: =A29/A28-1 -> 0.0017152659 | G28: =B29/B28-1 -> 0.0030349014 | H28: =C29/C28-1 -> 0.0067567568 | I28: =D29/D28-1 -> 0.015075377 | L28: -7.3183647e-19 | M28: -1.517883e-17 | N28: 1 | O28: -6.9388939e-18 | R28: -9.74 | S28: =1-R28 -> 10.74 | T28: =SQRT(R28^2*$L$48+S28^2*$L$49+2*R28*S28*$L$50) -> 0.44472246 | U28: =R28*$L$46+S28*$L$47 -> 0.71546041 | V28: =U28/T28 -> 1.6087796 | W28: =T28/U28 -> 0.6215892
A29: 292 | B29: 66.1 | C29: 149 | D29: 80.8 | F29: =A30/A29-1 -> 0.0017123288 | G29: =B30/B29-1 -> 0.0060514372 | H29: =C30/C29-1 -> 0.030201342 | I29: =D30/D29-1 -> -0.0012376238 | L29: -8.6736174e-19 | M29: -2.7755576e-17 | N29: 8.6736174e-19 | O29: 1 | R29: -9.73 | S29: =1-R29 -> 10.73 | T29: =SQRT(R29^2*$L$48+S29^2*$L$49+2*R29*S29*$L$50) -> 0.44442685 | U29: =R29*$L$46+S29*$L$47 -> 0.71513058 | V29: =U29/T29 -> 1.6091075 | W29: =T29/U29 -> 0.62146252
A30: 292.5 | B30: 66.5 | C30: 153.5 | D30: 80.7 | F30: =A31/A30-1 -> -0.0051282051 | G30: =B31/B30-1 -> -0.0030075188 | H30: =C31/C30-1 -> 0.009771987 | I30: =D31/D30-1 -> 0.016109046 | R30: -9.72 | S30: =1-R30 -> 10.72 | T30: =SQRT(R30^2*$L$48+S30^2*$L$49+2*R30*S30*$L$50) -> 0.44413126 | U30: =R30*$L$46+S30*$L$47 -> 0.71480074 | V30: =U30/T30 -> 1.6094358 | W30: =T30/U30 -> 0.62133575
A31: 291 | B31: 66.3 | C31: 155 | D31: 82 | F31: =A32/A31-1 -> 0.0085910653 | G31: =B32/B31-1 -> 0.0030165913 | H31: =C32/C31-1 -> 0.048387097 | I31: =D32/D31-1 -> -0.0085365854 | R31: -9.71 | S31: =1-R31 -> 10.71 | T31: =SQRT(R31^2*$L$48+S31^2*$L$49+2*R31*S31*$L$50) -> 0.44383568 | U31: =R31*$L$46+S31*$L$47 -> 0.7144709 | V31: =U31/T31 -> 1.6097644 | W31: =T31/U31 -> 0.6212089
A32: 293.5 | B32: 66.5 | C32: 162.5 | D32: 81.3 | F32: =A33/A32-1 -> -0.003407155 | G32: =B33/B32-1 -> 0.0015037594 | H32: =C33/C32-1 -> -0.018461538 | I32: =D33/D32-1 -> -0.023370234 | K32: Px | L32: dx | M32: 0.05 | R32: -9.7 | S32: =1-R32 -> 10.7 | T32: =SQRT(R32^2*$L$48+S32^2*$L$49+2*R32*S32*$L$50) -> 0.44354013 | U32: =R32*$L$46+S32*$L$47 -> 0.71414107 | V32: =U32/T32 -> 1.6100935 | W32: =T32/U32 -> 0.62108196
A33: 292.5 | B33: 66.6 | C33: 159.5 | D33: 79.4 | F33: =A34/A33-1 -> 0.0085470085 | G33: =B34/B33-1 -> 0.0045045045 | H33: =C34/C33-1 -> 0.0031347962 | I33: =D34/D33-1 -> 0 | K33: Zx | L33: 2308 | M33: 2881 | N33: 2603 | O33: 4904 | R33: -9.69 | S33: =1-R33 -> 10.69 | T33: =SQRT(R33^2*$L$48+S33^2*$L$49+2*R33*S33*$L$50) -> 0.4432446 | U33: =R33*$L$46+S33*$L$47 -> 0.71381123 | V33: =U33/T33 -> 1.6104229 | W33: =T33/U33 -> 0.62095492
A34: 295 | B34: 66.9 | C34: 160 | D34: 79.4 | F34: =A35/A34-1 -> -0.020338983 | G34: =B35/B34-1 -> 0 | H34: =C35/C34-1 -> -0.003125 | I34: =D35/D34-1 -> -0.0088161209 | L34: {=MMULT(K2:N2-$M$32,_xlfn.ANCHORARRAY(L20))} -> 2.7256996 | M34: 5.2031911 | N34: 2.2720203 | O34: 1.5606348 | P34: =SUM(_xlfn.ANCHORARRAY(L34)) -> 11.761546 | R34: -9.68 | S34: =1-R34 -> 10.68 | T34: =SQRT(R34^2*$L$48+S34^2*$L$49+2*R34*S34*$L$50) -> 0.44294909 | U34: =R34*$L$46+S34*$L$47 -> 0.7134814 | V34: =U34/T34 -> 1.6107526 | W34: =T34/U34 -> 0.6208278
A35: 289 | B35: 66.9 | C35: 159.5 | D35: 78.7 | F35: =A36/A35-1 -> 0.019031142 | G35: =B36/B35-1 -> 0.016442451 | H35: =C36/C35-1 -> 0.037617555 | I35: =D36/D35-1 -> 0 | K35: Wx | L35: 2308 | M35: 2881 | N35: 2603 | O35: 4904 | R35: -9.67 | S35: =1-R35 -> 10.67 | T35: =SQRT(R35^2*$L$48+S35^2*$L$49+2*R35*S35*$L$50) -> 0.4426536 | U35: =R35*$L$46+S35*$L$47 -> 0.71315156 | V35: =U35/T35 -> 1.6110827 | W35: =T35/U35 -> 0.62070059
A36: 294.5 | B36: 68 | C36: 165.5 | D36: 78.7 | F36: =A37/A36-1 -> -0.0033955857 | G36: =B37/B36-1 -> -0.0088235294 | H36: =C37/C36-1 -> -0.003021148 | I36: =D37/D36-1 -> -0.011435832 | L36: =L34/$P$34 -> 0.23174671 | M36: =M34/$P$34 -> 0.44239007 | N36: =N34/$P$34 -> 0.19317362 | O36: =O34/$P$34 -> 0.1326896 | P36: =SUM(L36:O36) -> 1 | R36: -9.66 | S36: =1-R36 -> 10.66 | T36: =SQRT(R36^2*$L$48+S36^2*$L$49+2*R36*S36*$L$50) -> 0.44235813 | U36: =R36*$L$46+S36*$L$47 -> 0.71282173 | V36: =U36/T36 -> 1.6114132 | W36: =T36/U36 -> 0.62057329
A37: 293.5 | B37: 67.4 | C37: 165 | D37: 77.8 | F37: =A38/A37-1 -> 0 | G37: =B38/B37-1 -> 0 | H37: =C38/C37-1 -> 0.042424242 | I37: =D38/D37-1 -> -0.0025706941 | R37: -9.65 | S37: =1-R37 -> 10.65 | T37: =SQRT(R37^2*$L$48+S37^2*$L$49+2*R37*S37*$L$50) -> 0.44206267 | U37: =R37*$L$46+S37*$L$47 -> 0.71249189 | V37: =U37/T37 -> 1.6117441 | W37: =T37/U37 -> 0.6204459
A38: 293.5 | B38: 67.4 | C38: 172 | D38: 77.6 | F38: =A39/A38-1 -> -0.010221465 | G38: =B39/B38-1 -> -0.0014836795 | H38: =C39/C38-1 -> 0.0087209302 | I38: =D39/D38-1 -> -0.0051546392 | R38: -9.64 | S38: =1-R38 -> 10.64 | T38: =SQRT(R38^2*$L$48+S38^2*$L$49+2*R38*S38*$L$50) -> 0.44176724 | U38: =R38*$L$46+S38*$L$47 -> 0.71216205 | V38: =U38/T38 -> 1.6120753 | W38: =T38/U38 -> 0.62031843
A39: 290.5 | B39: 67.3 | C39: 173.5 | D39: 77.2 | F39: =A40/A39-1 -> 0.015490534 | G39: =B40/B39-1 -> 0 | H39: =C40/C39-1 -> -0.011527378 | I39: =D40/D39-1 -> 0.010362694 | K39: Py | L39: dy | M39: 0.105 | R39: -9.63 | S39: =1-R39 -> 10.63 | T39: =SQRT(R39^2*$L$48+S39^2*$L$49+2*R39*S39*$L$50) -> 0.44147183 | U39: =R39*$L$46+S39*$L$47 -> 0.71183222 | V39: =U39/T39 -> 1.6124069 | W39: =T39/U39 -> 0.62019086
A40: 295 | B40: 67.3 | C40: 171.5 | D40: 78 | F40: =A41/A40-1 -> 0.006779661 | G40: =B41/B40-1 -> 0.011887073 | H40: =C41/C40-1 -> 0.034985423 | I40: =D41/D40-1 -> -0.012820513 | K40: Zy | L40: 2308 | M40: 2881 | N40: 2603 | O40: 4904 | R40: -9.62 | S40: =1-R40 -> 10.62 | T40: =SQRT(R40^2*$L$48+S40^2*$L$49+2*R40*S40*$L$50) -> 0.44117645 | U40: =R40*$L$46+S40*$L$47 -> 0.71150238 | V40: =U40/T40 -> 1.6127388 | W40: =T40/U40 -> 0.6200632
...
